<?xml version="1.0"?>
<robot xmlns:xacro="http://www.ros.org/wiki/xacro">

  <!-- Newton Gripper Macro -->
  <xacro:macro name="newton_gripper" params="name parent xyz rpy">
    <joint name="${name}_base_joint" type="fixed">
      <parent link="${parent}"/>
      <child link="${name}_base_link"/>
      <origin xyz="${xyz}" rpy="${rpy}"/>
    </joint>
    
    <link name="${name}_base_link">
      <inertial>
        <mass value="0.2"/>
        <origin xyz="0 0 0" rpy="0 0 0"/>
        <inertia ixx="0.0001" ixy="0.0" ixz="0.0" iyy="0.0001" iyz="0.0" izz="0.0001"/>
      </inertial>
      
      <visual>
        <origin xyz="0 0 0" rpy="0 0 0"/>
        <geometry>
          <box size="0.05 0.05 0.05"/>
        </geometry>
        <material name="grey"/>
      </visual>
      
      <collision>
        <origin xyz="0 0 0" rpy="0 0 0"/>
        <geometry>
          <box size="0.05 0.05 0.05"/>
        </geometry>
      </collision>
    </link>
    
    <!-- Left Jaw -->
    <joint name="${name}_left_joint" type="revolute">
      <parent link="${name}_base_link"/>
      <child link="${name}_left_link"/>
      <origin xyz="0.03 0.025 0" rpy="0 0 0"/>
      <axis xyz="0 0 1"/>
      <limit lower="0" upper="0.7" effort="10" velocity="1.0"/>
    </joint>
    
    <link name="${name}_left_link">
      <inertial>
        <mass value="0.05"/>
        <origin xyz="0.025 0 0" rpy="0 0 0"/>
        <inertia ixx="0.00001" ixy="0.0" ixz="0.0" iyy="0.00001" iyz="0.0" izz="0.00001"/>
      </inertial>
      
      <visual>
        <origin xyz="0.025 0 0" rpy="0 0 0"/>
        <geometry>
          <box size="0.05 0.01 0.02"/>
        </geometry>
        <material name="orange"/>
      </visual>
      
      <collision>
        <origin xyz="0.025 0 0" rpy="0 0 0"/>
        <geometry>
          <box size="0.05 0.01 0.02"/>
        </geometry>
      </collision>
    </link>
    
    <!-- Right Jaw -->
    <joint name="${name}_right_joint" type="revolute">
      <parent link="${name}_base_link"/>
      <child link="${name}_right_link"/>
      <origin xyz="0.03 -0.025 0" rpy="0 0 0"/>
      <axis xyz="0 0 1"/>
      <limit lower="-0.7" upper="0" effort="10" velocity="1.0"/>
      <mimic joint="${name}_left_joint" multiplier="-1" offset="0"/>
    </joint>
    
    <link name="${name}_right_link">
      <inertial>
        <mass value="0.05"/>
        <origin xyz="0.025 0 0" rpy="0 0 0"/>
        <inertia ixx="0.00001" ixy="0.0" ixz="0.0" iyy="0.00001" iyz="0.0" izz="0.00001"/>
      </inertial>
      
      <visual>
        <origin xyz="0.025 0 0" rpy="0 0 0"/>
        <geometry>
          <box size="0.05 0.01 0.02"/>
        </geometry>
        <material name="orange"/>
      </visual>
      
      <collision>
        <origin xyz="0.025 0 0" rpy="0 0 0"/>
        <geometry>
          <box size="0.05 0.01 0.02"/>
        </geometry>
      </collision>
    </link>
    
    <!-- Gazebo plugin for gripper -->
    <gazebo>
      <plugin name="${name}_mimic_joint_plugin" filename="libgazebo_mimic_joint_plugin.so">
        <joint>${name}_left_joint</joint>
        <mimicJoint>${name}_right_joint</mimicJoint>
        <multiplier>-1.0</multiplier>
        <offset>0.0</offset>
        <maxEffort>100.0</maxEffort>
      </plugin>
    </gazebo>
    
    <gazebo>
      <plugin name="${name}_gripper_plugin" filename="libgazebo_ros_control.so">
        <robotNamespace>${name}</robotNamespace>
      </plugin>
    </gazebo>
  </xacro:macro>

</robot>
