<?xml version="1.0"?>
<robot xmlns:xacro="http://www.ros.org/wiki/xacro">

  <!-- Constants -->
  <xacro:property name="pi" value="3.1415926535897931" />
  
  <!-- T200 Thruster Macro -->
  <xacro:macro name="t200_thruster" params="name parent xyz rpy">
    <joint name="${name}_joint" type="fixed">
      <parent link="${parent}"/>
      <child link="${name}_link"/>
      <origin xyz="${xyz}" rpy="${rpy}"/>
    </joint>
    
    <link name="${name}_link">
      <inertial>
        <mass value="0.35"/>
        <origin xyz="0 0 0" rpy="0 0 0"/>
        <inertia ixx="0.001" ixy="0.0" ixz="0.0" iyy="0.001" iyz="0.0" izz="0.001"/>
      </inertial>
      
      <visual>
        <origin xyz="0 0 0" rpy="0 0 0"/>
        <geometry>
          <cylinder radius="0.05" length="0.1"/>
        </geometry>
        <material name="black"/>
      </visual>
      
      <collision>
        <origin xyz="0 0 0" rpy="0 0 0"/>
        <geometry>
          <cylinder radius="0.05" length="0.1"/>
        </geometry>
      </collision>
    </link>
    
    <!-- Propeller -->
    <joint name="${name}_prop_joint" type="continuous">
      <parent link="${name}_link"/>
      <child link="${name}_prop_link"/>
      <origin xyz="0 0 0.06" rpy="0 0 0"/>
      <axis xyz="0 0 1"/>
    </joint>
    
    <link name="${name}_prop_link">
      <inertial>
        <mass value="0.01"/>
        <origin xyz="0 0 0" rpy="0 0 0"/>
        <inertia ixx="0.0001" ixy="0.0" ixz="0.0" iyy="0.0001" iyz="0.0" izz="0.0001"/>
      </inertial>
      
      <visual>
        <origin xyz="0 0 0" rpy="0 0 0"/>
        <geometry>
          <cylinder radius="0.04" length="0.01"/>
        </geometry>
        <material name="orange"/>
      </visual>
      
      <collision>
        <origin xyz="0 0 0" rpy="0 0 0"/>
        <geometry>
          <cylinder radius="0.04" length="0.01"/>
        </geometry>
      </collision>
    </link>
    
    <!-- Gazebo plugin for thruster -->
    <gazebo>
      <plugin name="${name}_thruster_plugin" filename="libgazebo_ros_force.so">
        <bodyName>${name}_prop_link</bodyName>
        <topicName>${name}/thrust</topicName>
        <frameName>${name}_prop_link</frameName>
      </plugin>
    </gazebo>
  </xacro:macro>

</robot>
